Workbook

Sheet Récap personnages
C1: ADT — Récapitulatif des personnages
C2: Les 20 troufions, puis les trois PJ, tous Évêques Sombres. Cellules jaunes = donnée jamais postée ; rouges = écart avec le barème. Le barème ne vaut que pour les troufions : « n/a » ailleurs.
A4: Portrait cultiste | B4: Portrait civil | C4: Alias | D4: Nom / Prénom | E4: Âge | F4: Statut | G4: Joueur | H4: Groupe | I4: Badges | J4: Nb compét. | K4: Budget compét. | L4: Budget attendu | M4: Écart | N4: Nb Pokémon | O4: Nb attendu | P4: Écart | Q4: Compétences (détail) | R4: Traits principaux | S4: Background | T4: Atouts croisés
C5: Frère Boule | F5: Troufion | H5: Groupe 1 - Famille Raccourci | I5: 5 | J5: =COUNTIFS(Compétences!$A$2:$A$101,$A5) | K5: =IF($H5=0,"",SUMPRODUCT((Compétences!$A$2:$A$101=$A5)*ABS(Compétences!$F$2:$F$101))) | L5: =IF($D5<>"Troufion","n/a",2+2*$G5) | M5: =IF($D5<>"Troufion","n/a",IF($H5=0,"n/c",$I5-$J5)) | N5: =COUNTIFS('Équipes Pokémon'!$A$2:$A$115,$A5) | O5: =IF($D5<>"Troufion","n/a",MIN($G5+2,6)) | P5: =IF($D5<>"Troufion","n/a",IF($L5=0,"n/c",$L5-$M5)) | Q5: Baston +4, Stratégie +3, Athlétisme +2, Coach +2, Infiltration +1 | R5: Très peu bavard - Chafouin sur sa calvitie - Geôlier de la secte | S5: Leader de la famille Raccourci, fils de Frère Fouras et père des enfants Raccourci. Très peu bavard, il préfère laisser parler la force pour faire passer ses messages. L'état de sa pilosité crânienne le rend chafouin. On dit qu'il enferme dans la cave familiale tous ceux qui font une remarque de trop sur ce sujet. Contribue à la secte comme geôlier, bien qu'il ne soit pas rapide pour intervenir en cas d'incident.
C6: Frère Jack | F6: Troufion | H6: Groupe 2 | I6: 5 | J6: =COUNTIFS(Compétences!$A$2:$A$101,$A6) | K6: =IF($H6=0,"",SUMPRODUCT((Compétences!$A$2:$A$101=$A6)*ABS(Compétences!$F$2:$F$101))) | L6: =IF($D6<>"Troufion","n/a",2+2*$G6) | M6: =IF($D6<>"Troufion","n/a",IF($H6=0,"n/c",$I6-$J6)) | N6: =COUNTIFS('Équipes Pokémon'!$A$2:$A$115,$A6) | O6: =IF($D6<>"Troufion","n/a",MIN($G6+2,6)) | P6: =IF($D6<>"Troufion","n/a",IF($L6=0,"n/c",$L6-$M6)) | Q6: Ésotérisme +5, Stratégie +4, Secourisme +2, Théologie +1 | R6: Brillant - Trop curieux - Légiste et médecin marron - Tarifs indexés sur la fortune du patient | S6: Étudiant en médecine brillant et curieux, trop curieux. Son intérêt grandissant pour les pratiques rituelles et pour la source physique de l'énergie dans un corps lui a valu d'être mis au ban du monde médical. Ces envies ont trouvé écho chez les ADT, où il peut les exercer à loisir. À la fois légiste et médecin marron, il est sollicité par des personnes fortunées aux maladies rares ou incurables, qui ont besoin de son savoir-faire excentrique et ésotérique mais néanmoins efficace. Ses services ont un coût à la hauteur de la fortune de ses patients, sauf pour ceux qu'il chérit. Il est ainsi l'un des soigneurs principaux chez les ADT. Il lui arrive aussi de prendre part aux rituels avec Dark Pommier, avec ses scalpels chargés en énergie ésotérique et son fidèle Unjoy. | T6: À DÉFINIR
C7: Frère Pierrot | D7: Baudet, Achille (identité officielle : John Doe) | E7: 29 ans | F7: Troufion | H7: Groupe 4 | I7: 5 | J7: =COUNTIFS(Compétences!$A$2:$A$101,$A7) | K7: =IF($H7=0,"",SUMPRODUCT((Compétences!$A$2:$A$101=$A7)*ABS(Compétences!$F$2:$F$101))) | L7: =IF($D7<>"Troufion","n/a",2+2*$G7) | M7: =IF($D7<>"Troufion","n/a",IF($H7=0,"n/c",$I7-$J7)) | N7: =COUNTIFS('Équipes Pokémon'!$A$2:$A$115,$A7) | O7: =IF($D7<>"Troufion","n/a",MIN($G7+2,6)) | P7: =IF($D7<>"Troufion","n/a",IF($L7=0,"n/c",$L7-$M7)) | Q7: Baston +4, Infiltrateur +3, Psychologue +2, Athlétisme +2, Observateur +1 | R7: Enjoué - Théâtral - Absolument sans foi ni loi - Ne s'intéresse qu'aux adversaires qui souffrent bien et aux forts moins puissants que lui - Ponctuel - Poli (quand il n'est pas dans un état second) - Psychopathe - Sociopathe - Sadomasochiste | S7: Équilibriste puis clown blanc dans un cirque itinérant de la côte. Six disparitions le long de la tournée entre Bordeleaux et Ajaxcité en quatre ans ; aucune enquête n'a abouti, parce que le cirque était déjà à trois villes de là. Les ADT ne l'ont pas converti : ils lui ont proposé un approvisionnement régulier en victimes. Il a dit oui avant la fin de la phrase, tout en tranchant la gorge d'un frère pas convaincu par ses capacités. Il assiste aux offices, connaît les cantiques par cœur, et n'a jamais cru un mot de rien. Les Évêques le savent et s'en accommodent tant qu'il est utile à la cause.
C8: Frère Rapace | F8: Troufion | H8: Groupe 3 | I8: 5 | J8: =COUNTIFS(Compétences!$A$2:$A$101,$A8) | K8: =IF($H8=0,"",SUMPRODUCT((Compétences!$A$2:$A$101=$A8)*ABS(Compétences!$F$2:$F$101))) | L8: =IF($D8<>"Troufion","n/a",2+2*$G8) | M8: =IF($D8<>"Troufion","n/a",IF($H8=0,"n/c",$I8-$J8)) | N8: =COUNTIFS('Équipes Pokémon'!$A$2:$A$115,$A8) | O8: =IF($D8<>"Troufion","n/a",MIN($G8+2,6)) | P8: =IF($D8<>"Troufion","n/a",IF($L8=0,"n/c",$L8-$M8)) | Q8: Stratégie +3, Marchandage +5, Psychologie +2, Observateur +2 | R8: Porte de préférence un masque à bec de rapace - Maire de Corrésone | S8: Maire de Corrésone. Sa vie a été sauvée par Sœur Automne lors du raid, face à l'attaque Ultralaser d'Olivier. | T8: À DÉFINIR
C9: Frère Dictateur | D9: Kyembé Prospère Junior Cornélius Parfait Mufasa Dieudonné Mobutu (« Kyky ») | E9: 22 ans | F9: Troufion | H9: Groupe 4 | I9: 4 | J9: =COUNTIFS(Compétences!$A$2:$A$101,$A9) | K9: =IF($H9=0,"",SUMPRODUCT((Compétences!$A$2:$A$101=$A9)*ABS(Compétences!$F$2:$F$101))) | L9: =IF($D9<>"Troufion","n/a",2+2*$G9) | M9: =IF($D9<>"Troufion","n/a",IF($H9=0,"n/c",$I9-$J9)) | N9: =COUNTIFS('Équipes Pokémon'!$A$2:$A$115,$A9) | O9: =IF($D9<>"Troufion","n/a",MIN($G9+2,6)) | P9: =IF($D9<>"Troufion","n/a",IF($L9=0,"n/c",$L9-$M9)) | Q9: Stratège +4, Coach +3, Social +2, Athlétisme +1 | R9: Imbu de lui-même - Autoritaire - Réellement brillant - Mauvais perdant - Générosité imprévisible - Moqueur - Leader | S9: Fils d'un chef d'État du Ma'Greb, envoyé faire ses études à Kalos. Personne dans son entourage n'a vérifié laquelle des deux Kalos. Il a atterri au Sud avec des papiers d'étudiant et a découvert trop tard qu'entrer au Nord avec une carte du Sud est interdit ; impossible pour lui également de rentrer chez lui. Il est piégé. Les ADT ne lui ont pas menti sur leur nature, ils lui ont promis une sortie du territoire et la gloire éternelle. Excellent élément, prêt à tout pour la victoire. Fort, mais pas dangereux : il gagne des combats, n'a jamais fait de mal à personne et n'en a aucune envie — mais ce n'est pas pour autant qu'il empêchera ses collègues d'en faire. Il se présente en récitant le protocole officiel du Ma'Greb, qui s'allonge à chaque présentation.
C10: Frère Fouras | F10: Troufion | H10: Groupe 1 - Famille Raccourci | I10: 4 | J10: =COUNTIFS(Compétences!$A$2:$A$101,$A10) | K10: =IF($H10=0,"",SUMPRODUCT((Compétences!$A$2:$A$101=$A10)*ABS(Compétences!$F$2:$F$101))) | L10: =IF($D10<>"Troufion","n/a",2+2*$G10) | M10: =IF($D10<>"Troufion","n/a",IF($H10=0,"n/c",$I10-$J10)) | N10: =COUNTIFS('Équipes Pokémon'!$A$2:$A$115,$A10) | O10: =IF($D10<>"Troufion","n/a",MIN($G10+2,6)) | P10: =IF($D10<>"Troufion","n/a",IF($L10=0,"n/c",$L10-$M10)) | Q10: Psychologie +4, Stratégie +3, Naturalisme +2, Observation +1 | R10: Manie la disruption adverse à l'aide de petites énigmes | S10: Patriarche de la famille Raccourci. Bon dresseur, son niveau de stratégie a diminué avec l'âge. Il manie la disruption adverse avec brio à l'aide de petites énigmes simples mais qui demandent un peu de réflexion.
C11: Frère Maskass | D11: d'Orcemont, Henri | E11: 27 ans | F11: Troufion | H11: Groupe 3 | I11: 4 | J11: =COUNTIFS(Compétences!$A$2:$A$101,$A11) | K11: =IF($H11=0,"",SUMPRODUCT((Compétences!$A$2:$A$101=$A11)*ABS(Compétences!$F$2:$F$101))) | L11: =IF($D11<>"Troufion","n/a",2+2*$G11) | M11: =IF($D11<>"Troufion","n/a",IF($H11=0,"n/c",$I11-$J11)) | N11: =COUNTIFS('Équipes Pokémon'!$A$2:$A$115,$A11) | O11: =IF($D11<>"Troufion","n/a",MIN($G11+2,6)) | P11: =IF($D11<>"Troufion","n/a",IF($L11=0,"n/c",$L11-$M11)) | Q11: Baston +2, Stratège +2, Social +2, Observateur +2, Théologie +2 | R11: Aigri - Renfermé - Sarcasme défensif permanent - Charismatique mais furieux que ça ne lui serve plus à rien - Ne supporte pas la pitié, encore moins la gentillesse | S11: Fils d'Évêque, élevé dans la secte, promis à tout, et surtout beau et charismatique. Il a été défiguré récemment : la moitié droite du visage est détruite. Depuis, il porte un masque et ne le retire devant personne. Il a cessé d'aller aux repas communs, puis aux offices non obligatoires, puis de répondre autrement que par le strict nécessaire. Il reste un bon élément de terrain et il le sait, ce qui le rend d'autant plus amer que ce soit désormais la seule chose qu'on lui reconnaisse. Souvent avec Dark, contre son gré, mais c'est ce que veut le grand chef.
C12: Sœur Vouivre | D12: Aveline, Sérène | E12: 43 ans | F12: Troufion | H12: Groupe 2 | I12: 4 | J12: =COUNTIFS(Compétences!$A$2:$A$101,$A12) | K12: =IF($H12=0,"",SUMPRODUCT((Compétences!$A$2:$A$101=$A12)*ABS(Compétences!$F$2:$F$101))) | L12: =IF($D12<>"Troufion","n/a",2+2*$G12) | M12: =IF($D12<>"Troufion","n/a",IF($H12=0,"n/c",$I12-$J12)) | N12: =COUNTIFS('Équipes Pokémon'!$A$2:$A$115,$A12) | O12: =IF($D12<>"Troufion","n/a",MIN($G12+2,6)) | P12: =IF($D12<>"Troufion","n/a",IF($L12=0,"n/c",$L12-$M12)) | Q12: Théologie +4, Chuchoteur +2, Ésotérisme +2, Secourisme +1, Observateur +1 | R12: Douce - Souriante - Absolument inébranlable - Aucune agressivité apparente - Zélée - Obsessionnelle | S12: Prêtresse de l'Église des dragons légendaires (Reshiram, Zekrom, Kyurem) pendant presque toute sa vie. Puis un type sans formation, sans ordination et sans le moindre respect pour la liturgie s'est mis à produire des miracles qui se réalisaient vraiment : le Prophète Azad. Elle n'a pas perdu la foi, elle a changé de destinataire. Pour une théologienne de carrière, les ADT sont la première religion honnête qu'elle rencontre : des résultats mesurables, contre un prix clairement énoncé, dans un cadre rituel rigoureux. Elle refuse la fusion et le dit ouvertement, ce que personne d'autre n'ose : coller deux créatures ensemble avec de la matière volée est une profanation de l'ordre que les dragons incarnent. Sur ce point précis, elle est plus intransigeante que les Évêques. Point sensible : fixation amoureuse morbide sur les dresseurs possédant de puissants Pokémon reptiliens — elle collectionne les informations sur eux, apprend leurs trajets, leur écrit des lettres qu'elle n'envoie pas, et considère qu'ils lui appartiennent déjà. Parfaitement fonctionnelle et courtoise le reste du temps, ce qui rend la chose difficile à signaler.
C13: Frère Menu | F13: Troufion | H13: Groupe 2 | I13: 3 | J13: =COUNTIFS(Compétences!$A$2:$A$101,$A13) | K13: =IF($H13=0,"",SUMPRODUCT((Compétences!$A$2:$A$101=$A13)*ABS(Compétences!$F$2:$F$101))) | L13: =IF($D13<>"Troufion","n/a",2+2*$G13) | M13: =IF($D13<>"Troufion","n/a",IF($H13=0,"n/c",$I13-$J13)) | N13: =COUNTIFS('Équipes Pokémon'!$A$2:$A$115,$A13) | O13: =IF($D13<>"Troufion","n/a",MIN($G13+2,6)) | P13: =IF($D13<>"Troufion","n/a",IF($L13=0,"n/c",$L13-$M13)) | Q13: Coach +5, Stratégie +1, Athlétisme -2 | R13: Ancien sportif déchu - Client fidèle de la pizzéria de Dark | S13: Ancien grand sportif ayant participé au Pokéathlon, tombé en déchéance après plusieurs accusations diverses. Il prend sa revanche au travers des ADT. Client extrêmement fidèle à la pizzéria de Dark. | T13: À DÉFINIR
C14: Sœur Dame Blanche | F14: Troufion | H14: Groupe 1 - Famille Raccourci | I14: 3 | J14: =COUNTIFS(Compétences!$A$2:$A$101,$A14) | K14: =IF($H14=0,"",SUMPRODUCT((Compétences!$A$2:$A$101=$A14)*ABS(Compétences!$F$2:$F$101))) | L14: =IF($D14<>"Troufion","n/a",2+2*$G14) | M14: =IF($D14<>"Troufion","n/a",IF($H14=0,"n/c",$I14-$J14)) | N14: =COUNTIFS('Équipes Pokémon'!$A$2:$A$115,$A14) | O14: =IF($D14<>"Troufion","n/a",MIN($G14+2,6)) | P14: =IF($D14<>"Troufion","n/a",IF($L14=0,"n/c",$L14-$M14)) | Q14: Papilusion Social +3, Stratégie +2, Psychologue +2, Coach +1 | R14: Très belle - Caractère très cruel - En quête de l'amour de sa vie | S14: Seule fille de la famille Raccourci. Elle se distingue par un visage d'une grande beauté, et par un caractère très cruel. Elle profite de sa quête des badges pour rechercher l'amour de sa vie. Tout jeune homme de moins de 1m90 est prié de passer son chemin.
C15: Sœur Gardienne | F15: Troufion | H15: Groupe 2 | I15: 3 | J15: =COUNTIFS(Compétences!$A$2:$A$101,$A15) | K15: =IF($H15=0,"",SUMPRODUCT((Compétences!$A$2:$A$101=$A15)*ABS(Compétences!$F$2:$F$101))) | L15: =IF($D15<>"Troufion","n/a",2+2*$G15) | M15: =IF($D15<>"Troufion","n/a",IF($H15=0,"n/c",$I15-$J15)) | N15: =COUNTIFS('Équipes Pokémon'!$A$2:$A$115,$A15) | O15: =IF($D15<>"Troufion","n/a",MIN($G15+2,6)) | P15: =IF($D15<>"Troufion","n/a",IF($L15=0,"n/c",$L15-$M15)) | Q15: Stratégie +2, Athlétisme +3, Observation +2, Baston +1 | R15: Désabusée - En deuil de son Pokémon partenaire | S15: Ranger désabusée, a sombré dans le désespoir suite à la mort de son Pokémon partenaire, un Négapi tombé au cours d'une opération spéciale. A rejoint les ADT qui lui ont promis le repos de son âme en échange de sa coopération.
C16: Sœur Pie | D16: Li, Sha — 李莎 | E16: 21 ans | F16: Troufion | H16: Groupe 4 | I16: 3 | J16: =COUNTIFS(Compétences!$A$2:$A$101,$A16) | K16: =IF($H16=0,"",SUMPRODUCT((Compétences!$A$2:$A$101=$A16)*ABS(Compétences!$F$2:$F$101))) | L16: =IF($D16<>"Troufion","n/a",2+2*$G16) | M16: =IF($D16<>"Troufion","n/a",IF($H16=0,"n/c",$I16-$J16)) | N16: =COUNTIFS('Équipes Pokémon'!$A$2:$A$115,$A16) | O16: =IF($D16<>"Troufion","n/a",MIN($G16+2,6)) | P16: =IF($D16<>"Troufion","n/a",IF($L16=0,"n/c",$L16-$M16)) | Q16: Social +2, Observateur +2, Psychologue +2, Infiltrateur +2 | R16: Bavarde compulsive - Curieuse de tout - Shippeuse invétérée - Loyale jusqu'à la bêtise - Terrifiée en permanence et incapable de le montrer autrement qu'en parlant plus - Peur des Insectes | S16: Née à Kanto, arrivée à Arescité à neuf ans quand ses parents ont été engagés comme intermédiaires sur une filière d'approvisionnement en gemmes kantoniennes. Domestiques de maison bourgeoise, logés au-dessus des ateliers, jamais tout à fait chez eux nulle part. Elle parle trop. Elle pose des questions auxquelles personne ne veut répondre. Elle tient un carnet où elle note qui regarde qui, et elle est absolument convaincue que ça n'intéresse personne d'autre qu'elle.
C17: Frère Bihainebi (Denis) | D17: Denis | F17: Troufion | H17: Groupe 2 | I17: 2 | J17: =COUNTIFS(Compétences!$A$2:$A$101,$A17) | K17: =IF($H17=0,"",SUMPRODUCT((Compétences!$A$2:$A$101=$A17)*ABS(Compétences!$F$2:$F$101))) | L17: =IF($D17<>"Troufion","n/a",2+2*$G17) | M17: =IF($D17<>"Troufion","n/a",IF($H17=0,"n/c",$I17-$J17)) | N17: =COUNTIFS('Équipes Pokémon'!$A$2:$A$115,$A17) | O17: =IF($D17<>"Troufion","n/a",MIN($G17+2,6)) | P17: =IF($D17<>"Troufion","n/a",IF($L17=0,"n/c",$L17-$M17)) | Q17: Marchand +3, Stratégie +1, Psychologue +1, Observation +1 | R17: Boomer - Propriétaire bailleur | S17: A trouvé du travail en allant parler au chef des rangers, lui. Pas besoin de 4 mois de balades comme les jeunes fainéants actuels. De son temps, on avait une Baie Oran à Noël et on ne s'en plaignait pas. A pu s'acheter une petite maison de 150 m² à 35 ans avec son salaire de gardien, puis une deuxième à 40 ans. A transité depuis sur le marché locatif.
C18: Frère Dump | F18: Troufion | H18: Groupe 2 | I18: 2 | J18: =COUNTIFS(Compétences!$A$2:$A$101,$A18) | K18: =IF($H18=0,"",SUMPRODUCT((Compétences!$A$2:$A$101=$A18)*ABS(Compétences!$F$2:$F$101))) | L18: =IF($D18<>"Troufion","n/a",2+2*$G18) | M18: =IF($D18<>"Troufion","n/a",IF($H18=0,"n/c",$I18-$J18)) | N18: =COUNTIFS('Équipes Pokémon'!$A$2:$A$115,$A18) | O18: =IF($D18<>"Troufion","n/a",MIN($G18+2,6)) | P18: =IF($D18<>"Troufion","n/a",IF($L18=0,"n/c",$L18-$M18)) | Q18: Stratégie +2, Marchandage +3, Technologie +1
C19: Frère Pump | F19: Troufion | H19: Groupe 2 | I19: 2 | J19: =COUNTIFS(Compétences!$A$2:$A$101,$A19) | K19: =IF($H19=0,"",SUMPRODUCT((Compétences!$A$2:$A$101=$A19)*ABS(Compétences!$F$2:$F$101))) | L19: =IF($D19<>"Troufion","n/a",2+2*$G19) | M19: =IF($D19<>"Troufion","n/a",IF($H19=0,"n/c",$I19-$J19)) | N19: =COUNTIFS('Équipes Pokémon'!$A$2:$A$115,$A19) | O19: =IF($D19<>"Troufion","n/a",MIN($G19+2,6)) | P19: =IF($D19<>"Troufion","n/a",IF($L19=0,"n/c",$L19-$M19)) | Q19: Stratégie +2, Marchandage +1, Technologie +3
C20: Frère Tigre | F20: Troufion | H20: Groupe 1 - Famille Raccourci | I20: 2 | J20: =COUNTIFS(Compétences!$A$2:$A$101,$A20) | K20: =IF($H20=0,"",SUMPRODUCT((Compétences!$A$2:$A$101=$A20)*ABS(Compétences!$F$2:$F$101))) | L20: =IF($D20<>"Troufion","n/a",2+2*$G20) | M20: =IF($D20<>"Troufion","n/a",IF($H20=0,"n/c",$I20-$J20)) | N20: =COUNTIFS('Équipes Pokémon'!$A$2:$A$115,$A20) | O20: =IF($D20<>"Troufion","n/a",MIN($G20+2,6)) | P20: =IF($D20<>"Troufion","n/a",IF($L20=0,"n/c",$L20-$M20)) | Q20: Infiltration +2, Athlétisme +2, Stratégie +1, Baston +1 | R20: Identité secrète, ne retire jamais son masque de tigre | S20: Dresseur à l'identité secrète, membre de la famille Raccourci. On ne sait pas très bien de quel enfant il s'agit car il ne retire jamais son masque de tigre. Si ça se trouve c'est un parfait inconnu. Lui aussi aspire à obtenir 3 badges sous peu. Il possède un double des clés de Frère Passe.
C21: Frère Junior | F21: Troufion | H21: Groupe 2 | I21: 1 | J21: =COUNTIFS(Compétences!$A$2:$A$101,$A21) | K21: =IF($H21=0,"",SUMPRODUCT((Compétences!$A$2:$A$101=$A21)*ABS(Compétences!$F$2:$F$101))) | L21: =IF($D21<>"Troufion","n/a",2+2*$G21) | M21: =IF($D21<>"Troufion","n/a",IF($H21=0,"n/c",$I21-$J21)) | N21: =COUNTIFS('Équipes Pokémon'!$A$2:$A$115,$A21) | O21: =IF($D21<>"Troufion","n/a",MIN($G21+2,6)) | P21: =IF($D21<>"Troufion","n/a",IF($L21=0,"n/c",$L21-$M21)) | Q21: Athlétisme +1, Stratégie +1, Coach +1, Papilusion Social +1 | R21: Orphelin - Allégeance arrachée sous la contrainte - Généraliste : un peu de tout, de quoi survivre mais pas de quoi vivre | S21: Orphelin capturé par les ADT (avec décès malencontreux de son protecteur) pour être sacrifié, qui a réussi à être épargné en suppliant ses geôliers d'avoir la vie sauve contre une allégeance envers le Pape Sombre. Envoyé sur la route des badges avec un petit Rattata en poche et pour seul ordre « Satisfais-nous ou bien nous nous satisferons de toi », il a réussi tant bien que mal à récupérer 1 badge et à agrandir son équipe.
C22: Frère Nasse | D22: Duflot, Séverin | E22: 52 ans | F22: Troufion | H22: Sans groupe (restants) | I22: 1 | J22: =COUNTIFS(Compétences!$A$2:$A$101,$A22) | K22: =IF($H22=0,"",SUMPRODUCT((Compétences!$A$2:$A$101=$A22)*ABS(Compétences!$F$2:$F$101))) | L22: =IF($D22<>"Troufion","n/a",2+2*$G22) | M22: =IF($D22<>"Troufion","n/a",IF($H22=0,"n/c",$I22-$J22)) | N22: =COUNTIFS('Équipes Pokémon'!$A$2:$A$115,$A22) | O22: =IF($D22<>"Troufion","n/a",MIN($G22+2,6)) | P22: =IF($D22<>"Troufion","n/a",IF($L22=0,"n/c",$L22-$M22)) | Q22: Survivaliste +1, Naturalisme +1, Construction +1, Marchand +1 | R22: Bougon - À son compte depuis toujours et le rappelle volontiers - Radin - Aucune opinion politique, que des griefs administratifs - A l'impression d'être constamment perdu et est complètement perdu - Nul - Naze | S22: « Duflot Élagage, abattage, bois de chauffage. Devis gratuit. Déplacement offert dans un rayon de 30 km. » Quatrième génération dans le métier. Il a repris l'affaire de son père à vingt ans, n'a jamais eu de patron de sa vie, et le fait savoir. Il abat, il débroussaille, il fait du charbon en meule six mois par an, il livre. Le régime lui a retiré son droit de coupe sur les Bois Noirs : nouvelle réglementation forestière, dossier à monter, formation obligatoire, attestation à renouveler tous les trois ans. Il a continué sans. Puis les ADT sont venus le voir avec la seule offre qui l'intéressait : du travail régulier, payé en liquide, sans paperasse. Il n'a aucune opinion sur le culte et personne ne lui en demande. Ce n'est pas un dresseur : il n'a jamais fait un badge et n'a aucune envie d'en faire.
C23: Frère Passe | F23: Troufion | H23: Groupe 1 - Famille Raccourci | I23: 1 | J23: =COUNTIFS(Compétences!$A$2:$A$101,$A23) | K23: =IF($H23=0,"",SUMPRODUCT((Compétences!$A$2:$A$101=$A23)*ABS(Compétences!$F$2:$F$101))) | L23: =IF($D23<>"Troufion","n/a",2+2*$G23) | M23: =IF($D23<>"Troufion","n/a",IF($H23=0,"n/c",$I23-$J23)) | N23: =COUNTIFS('Équipes Pokémon'!$A$2:$A$115,$A23) | O23: =IF($D23<>"Troufion","n/a",MIN($G23+2,6)) | P23: =IF($D23<>"Troufion","n/a",IF($L23=0,"n/c",$L23-$M23)) | Q23: Infiltration +2, Athlétisme +2 | S23: Dresseur petit mais vaillant, cadet de la famille Raccourci. Il affiche fièrement son objectif de réunir 3 badges sous peu, ainsi que des clés qui selon lui ouvriraient des salles cachées sur le fort.
C24: Sœur Ours | F24: Troufion | H24: Groupe 3 | I24: 1 | J24: =COUNTIFS(Compétences!$A$2:$A$101,$A24) | K24: =IF($H24=0,"",SUMPRODUCT((Compétences!$A$2:$A$101=$A24)*ABS(Compétences!$F$2:$F$101))) | L24: =IF($D24<>"Troufion","n/a",2+2*$G24) | M24: =IF($D24<>"Troufion","n/a",IF($H24=0,"n/c",$I24-$J24)) | N24: =COUNTIFS('Équipes Pokémon'!$A$2:$A$115,$A24) | O24: =IF($D24<>"Troufion","n/a",MIN($G24+2,6)) | P24: =IF($D24<>"Troufion","n/a",IF($L24=0,"n/c",$L24-$M24)) | Q24: Cuisine +1, Chuchoteur +2, Coach +1 | R24: Recrue récente - Pleine de colère contre le système Sud-Kalosien | S24: Mère célibataire ayant perdu la garde de ses deux filles suite à une série de manigances par son ex-conjoint, qui a ensuite fui vers le nord. Recrue récente voulant faire ses preuves, pleine de colère contre le système Sud-Kalosien.
C25: Frère Dark | D25: — (identité civile non communiquée à l'Ordre) | E25: 23 ans | F25: PJ — Évêque Sombre | G25: Dark-63 | H25: Groupe 3 | I25: 0 | J25: =COUNTIFS(Compétences!$A$2:$A$101,$A25) | K25: =IF($H25=0,"",SUMPRODUCT((Compétences!$A$2:$A$101=$A25)*ABS(Compétences!$F$2:$F$101))) | L25: =IF($D25<>"Troufion","n/a",2+2*$G25) | M25: =IF($D25<>"Troufion","n/a",IF($H25=0,"n/c",$I25-$J25)) | N25: =COUNTIFS('Équipes Pokémon'!$A$2:$A$115,$A25) | O25: =IF($D25<>"Troufion","n/a",MIN($G25+2,6)) | P25: =IF($D25<>"Troufion","n/a",IF($L25=0,"n/c",$L25-$M25)) | Q25: Coach +1, Stratège +3, Papillusion Social -2, Chuchoteur +1, Observateur +1, Athlétisme +2, Baston +4, Cuisine +4 | R25: Foi aveugle - Insensibilité de façade - Outil sans âme - Obéissance totale à l'Ordre - Ne retire jamais son gant droit | S25: Évêque Sombre, rattaché au groupe d'attaque du Frère Pommier. Aucune carte de dresseur : l'Ordre n'en délivre pas. Tient une pizzeria à Corrésone, le « Four à Bois », qui sert de couverture et de point de contact. 1m88, 84 kg. Gant noir en permanence à la main droite, jamais retiré en public. Parle kalosien (natif), galarien (fonctionnel), notions de kalosien antique. Le reste de son dossier n'est pas public.
C26: Modulo | D26: Aimé(e) de Saint — Run (Aimée) / Ren (Aimé) | F26: PJ — Évêque Sombre | G26: Avav | H26: Groupe 4 | J26: =COUNTIFS(Compétences!$A$2:$A$101,$A26) | K26: =IF($H26=0,"",SUMPRODUCT((Compétences!$A$2:$A$101=$A26)*ABS(Compétences!$F$2:$F$101))) | L26: =IF($D26<>"Troufion","n/a",2+2*$G26) | M26: =IF($D26<>"Troufion","n/a",IF($H26=0,"n/c",$I26-$J26)) | N26: =COUNTIFS('Équipes Pokémon'!$A$2:$A$115,$A26) | O26: =IF($D26<>"Troufion","n/a",MIN($G26+2,6)) | P26: =IF($D26<>"Troufion","n/a",IF($L26=0,"n/c",$L26-$M26)) | Q26: Coach +5, Baston +3, Stratégie +3, Observation +2, Papillusion Social +2, Secourisme +1, Psychologie -2 | R26: Run : scène, idol, Johto-pop et Kanto-pop, chorégraphies. Ren : combat rapproché, technique, armes blanches. Surnommé Modulo chez les ADT pour son tic de langage. Personnage très narcissique — d'où le malus en Psychologie | S26: Personnage à deux voix, Run et Ren, qui se partagent l'équipe en deux trios. Le trio de scène de Run (Moka, Ondine, BlackPink) est monté pour la représentation ; le trio de Ren (Moufette, Le gluant, Domina) pour le combat. Toute l'équipe maîtrise Charme et Attraction : adversaire charmé, adversaire qui n'attaque plus. Deux moyens de déplacement : le Téléport de Moka (inutilisable au repaire ou en zone enténébrée, l'aura Ténèbres le bloque, et suppose d'avoir repéré les lieux) et Domina en monture (peu discrète hors repaire ou hors offensive). | T26: À DÉFINIR
C27: Sœur Automne | F27: PJ — Évêque Sombre | G27: AkiMinoriko | H27: Groupe 3 | J27: =COUNTIFS(Compétences!$A$2:$A$101,$A27) | K27: =IF($H27=0,"",SUMPRODUCT((Compétences!$A$2:$A$101=$A27)*ABS(Compétences!$F$2:$F$101))) | L27: =IF($D27<>"Troufion","n/a",2+2*$G27) | M27: =IF($D27<>"Troufion","n/a",IF($H27=0,"n/c",$I27-$J27)) | N27: =COUNTIFS('Équipes Pokémon'!$A$2:$A$115,$A27) | O27: =IF($D27<>"Troufion","n/a",MIN($G27+2,6)) | P27: =IF($D27<>"Troufion","n/a",IF($L27=0,"n/c",$L27-$M27)) | Q27: Infiltration +5, Psychologue +3, Baston +3, Ésotérisme +2, Stratégie +2, Secourisme +1, Papillusion Social -2 | S27: A sauvé Frère Rapace lors du raid, de l'attaque Ultralaser d'Olivier. | T27: À DÉFINIR
C28: Sœur Aquila | D28: Serreval, Octavia | E28: 32 ans | F28: Troufion | H28: Groupe 5 - Escouade de raid | I28: 4 | Q28: Stratège +4, Coach +3, Observateur +1, Athlétisme +1, Chuchoteur +1 | R28: Sèche - Économe de ses mots - Rancunière - Compétente et parfaitement consciente de l'être - Ne se justifie jamais - Défend son engagement dans l'Ordre comme une décision réfléchie - Méprise les dresseurs qui n'ont pas mérité leur licence - Lit des présages dans le vol des oiseaux et n'en démord pas | S28: Dresseuse à l'arène Vol de Roseville pendant huit ans, entrée à vingt ans, affectée à l'épreuve thématique : faire passer l'examen du permis de Vol. Un poste sans prestige, mais avec un tampon. Elle a commencé par arranger le dossier d'un candidat qui avait échoué trois fois, puis par en arranger d'autres contre rétribution, jusqu'à ce qu'un de ses titulaires décroche de sa monture au-dessus des gorges de l'Imon. Olivier a remonté la filière en quatre jours et l'a renvoyée lui-même, sans crier, ce qu'elle lui pardonne encore moins. Les ADT sont venus la voir six semaines plus tard : ils n'avaient pas besoin d'une dresseuse, ils avaient besoin de quelqu'un capable de certifier. Elle a refusé. Elle se souvient d'avoir hésité, puis d'avoir accepté, et elle situe encore ce choix comme le sien ; entre les deux, il manque une soirée dont elle ne parle jamais parce qu'elle ne sait pas qu'elle manque. Sœur Psykos n'a eu besoin de pousser qu'une fois. Elle recrute désormais ses oiseaux sur les charniers et les décharges plutôt qu'en élevage, au motif qu'un charognard nourri à la main ne sait plus chercher. Elle a gardé le dossier du candidat qui est mort, et elle le relit.
C29: Frère Heaume | D29: Hycard, Thibault | E29: 38 ans | F29: Troufion | H29: Groupe 5 - Escouade de raid | I29: 3 | Q29: Baston +3, Stratégie +2, Théologie +2, Technologie +1 | R29: Méticuleux - Lent à décider et impossible à presser - Fier de son travail jusqu'à la susceptibilité - Condescendant envers les amateurs - Ne supporte pas qu'on touche à ses pièces sans gants - Indifférent aux causes, y compris celles de ses clients - Croyant sincère, ce qui est rare à son palier - Entêté | S29: Armurier de reconstitution historique, atelier en bas de Corrésone, spécialisé dans les pièces de tournoi du XIVe : heaumes à bassinet, gantelets articulés, épées de parade. Il fournissait les fêtes médiévales de la région, deux musées, et sans jamais y voir de politique, une bonne partie des costumes des QuillAnons. Ils payaient bien et commandaient des pièces intéressantes, cela lui suffisait. La réglementation sur les reproductions d'armes blanches, votée pour serrer la vis à ces mêmes Quills, l'a rattrapé sans le viser : il n'a pas voulu s'y plier, et la commande publique s'est arrêtée d'un coup. Les ADT ne lui ont pas parlé de l'Ombre en premier : ils lui ont montré l'armurerie du sanctuaire, des pièces qu'aucun collectionneur de la région ne verra jamais, et lui ont demandé qui s'en occupait. Personne ne s'en occupait. Il entretient depuis les lames rituelles, affûte le couteau sacrificiel avant chaque office et considère que c'est un honneur. Il a fini par croire pour de bon, quelque part entre la troisième et la quatrième année, à un âge où l'on ne s'attend plus à le voir arriver.
C30: Frère Piqueux | D30: Wicart, Jean | E30: 45 ans | F30: Troufion | H30: Groupe 5 - Escouade de raid | I30: 2 | Q30: Observation +3, Chuchoteur +2, Naturalisme +1 | R30: Taiseux - Tiré à quatre épingles en toutes circonstances - Parle aux Pokémons et très peu aux gens - Patient au point d'attendre des heures sans bouger - N'élève jamais la voix - Doux avec les Pokémons et indifférent au reste - Ne comprend pas la moitié de ce que l'Ordre raconte et ne cherche pas à comprendre | S30: Piqueux d'équipage sur un grand domaine en lisière des Bois Noirs, en livrée, au service d'une famille qui recevait : il nourrissait la meute, la soignait, la menait, et la connaissait chien par chien. Le domaine a été vendu, l'équipage dissous, et on lui a proposé de faire piquer les Pokémons chiens. Il est parti avec. Quatorze mois de braconnage et de petits travaux pour les nourrir, en dormant dans une cabane de bûcheron, avant que les ADT ne lui proposent des galeries à surveiller et de la viande tous les jours. Il n'a pas demandé pour quoi faire. Il a gardé de la maison l'habitude d'être impeccable et de ne jamais hausser le ton, ce qui le rend impossible à situer : les frères le prennent pour un tueur, alors qu'il est surtout appliqué. Il assiste aux offices parce qu'on le lui demande, s'assied au fond, et repart dès la fin. Ce n'est pas un dresseur au sens où l'Ordre l'entend : il ne donne pas d'ordres, il lit sa meute et la laisse faire. C'est précisément pour cette raison qu'il voit des choses que personne d'autre ne voit.
C31: Frère Miasme | D31: Kahananui, Maleko | E31: 44 ans | F31: Troufion | H31: Groupe 5 - Escouade de raid | I31: 2 | Q31: Infiltration +2, Technologie +2, Observation +1, Psychologue +1 | R31: Placide - Affable et jamais pressé - Insensible aux odeurs et aux dégoûts - Intarissable sur son métier et muet sur tout le reste - Ne s'attache à aucun de ses Pokémon et le dit sans gêne - Ponctuel - Traite tout le monde comme un usager, Évêques compris - Parle le kalosien sans le moindre accent et se l'entend faire remarquer quand même | S31: Né à Alola, arrivé à Corrésone à vingt-cinq ans et resté faute de mieux : dans une région où l'on croise peu d'étrangers, on ne lui a jamais proposé autre chose que le travail dont personne ne voulait. Dix-neuf ans de collecteurs et de galeries de visite au service d'assainissement. Il connaît le sous-sol de la ville mieux que la plupart des frères et sœurs, et pour une raison simple : les plans du service s'arrêtent au niveau -2, alors que le réseau continue. Il est tombé sur des portes scellées que personne n'avait cartographiées, a entendu du chant derrière, et a mis deux ans à trouver qui chantait. Ce n'est pas l'Ordre qui l'a recruté, c'est lui qui a fini par frapper : ils ont été les premiers à Corrésone à vouloir quelque chose de lui. Il ramasse ce qui vit dans les collecteurs et s'en sert comme d'un consommable, sans surnom et sans état d'âme. Il ne se bat pas pour gagner : il se bat pour que l'adversaire arrive usé sur le suivant, ce qu'il explique volontiers à qui ne lui a rien demandé. Affable, poli, jamais pressé : c'est ce qui met le plus mal à l'aise.
C33: TOTAL | I33: =SUM(G5:G31) | N33: =SUM(L5:L27) | Q33: =COUNTIF($D$5:$D$27,"Troufion")&" troufions + "&COUNTA(A5:A27)-COUNTIF($D$5:$D$27,"Troufion")&" PJ"
C35: Légende
C36: Groupe 1 - Famille Raccourci
C37: Groupe 2
C38: Groupe 3
C39: Groupe 4
C40: Sans groupe (restants)
C41: Personnage joueur (Évêque Sombre)
C42: Donnée jamais communiquée

Sheet Compétences
A1: Personnage | B1: Groupe | C1: Badges | D1: Compétence (telle que postée) | E1: Compétence officielle | F1: Valeur
A2: Frère Boule | B2: Groupe 1 - Famille Raccourci | C2: 5 | D2: Baston | E2: Baston | F2: 4
A3: Frère Boule | B3: Groupe 1 - Famille Raccourci | C3: 5 | D3: Stratégie | E3: Stratège | F3: 3
A4: Frère Boule | B4: Groupe 1 - Famille Raccourci | C4: 5 | D4: Athlétisme | E4: Athlétisme | F4: 2
A5: Frère Boule | B5: Groupe 1 - Famille Raccourci | C5: 5 | D5: Coach | E5: Coach | F5: 2
A6: Frère Boule | B6: Groupe 1 - Famille Raccourci | C6: 5 | D6: Infiltration | E6: Infiltrateur | F6: 1
A7: Frère Jack | B7: Sans groupe (restants) | C7: 5 | D7: Ésotérisme | E7: Ésotérisme | F7: 5
A8: Frère Jack | B8: Sans groupe (restants) | C8: 5 | D8: Stratégie | E8: Stratège | F8: 4
A9: Frère Jack | B9: Sans groupe (restants) | C9: 5 | D9: Secourisme | E9: Secourisme | F9: 2
A10: Frère Jack | B10: Sans groupe (restants) | C10: 5 | D10: Théologie | E10: Théologie | F10: 1
A11: Frère Pierrot | B11: Sans groupe (restants) | C11: 5 | D11: Baston | E11: Baston | F11: 4
A12: Frère Pierrot | B12: Sans groupe (restants) | C12: 5 | D12: Infiltrateur | E12: Infiltrateur | F12: 3
A13: Frère Pierrot | B13: Sans groupe (restants) | C13: 5 | D13: Psychologue | E13: Psychologue | F13: 2
... A87: Frère Dark | B87: Groupe 3 | C87: 0 | D87: Cuisine | E87: Cuisine | F87: 4
A88: Modulo | B88: Groupe 4 | D88: Coach | E88: Coach | F88: 5
A89: Modulo | B89: Groupe 4 | D89: Baston | E89: Baston | F89: 3
A90: Modulo | B90: Groupe 4 | D90: Stratégie | E90: Stratège | F90: 3
A91: Modulo | B91: Groupe 4 | D91: Observation | E91: Observateur | F91: 2
A92: Modulo | B92: Groupe 4 | D92: Papillusion Social | E92: Social | F92: 2
A93: Modulo | B93: Groupe 4 | D93: Secourisme | E93: Secourisme | F93: 1
A94: Modulo | B94: Groupe 4 | D94: Psychologie | E94: Psychologue | F94: -2
A95: Sœur Automne | B95: Groupe 3 | D95: Infiltration | E95: Infiltrateur | F95: 5
A96: Sœur Automne | B96: Groupe 3 | D96: Psychologue | E96: Psychologue | F96: 3
A97: Sœur Automne | B97: Groupe 3 | D97: Baston | E97: Baston | F97: 3
A98: Sœur Automne | B98: Groupe 3 | D98: Ésotérisme | E98: Ésotérisme | F98: 2
A99: Sœur Automne | B99: Groupe 3 | D99: Stratégie | E99: Stratège | F99: 2
... A101: Sœur Automne | B101: Groupe 3 | D101: Papillusion Social | E101: Social | F101: -2

Sheet Équipes Pokémon
A1: Personnage | B1: Groupe | C1: Badges | D1: N° | E1: Pokémon | F1: Surnom | G1: Genre | H1: Types | I1: Talent | J1: Objet | K1: Attaque 1 | L1: Attaque 2 | M1: Attaque 3 | N1: Attaque 4 | O1: Attaque 5 | P1: Attaque 6 | Q1: Nb attaques | R1: Notes (rôle, nature, combo)
A2: Frère Boule | B2: Groupe 1 - Famille Raccourci | C2: 5 | D2: 1 | E2: Floréclat | H2: Roche-Poison | I2: Dépôt Toxique | K2: Toupie Éclat | L2: Rayon Gemme | M2: Cradovague | N2: Telluriforce | O2: Explosion | P2: Picots | Q2: =COUNTA(K2:P2)
A3: Frère Boule | B3: Groupe 1 - Famille Raccourci | C3: 5 | D3: 2 | E3: Altaria | H3: Dragon-Vol | I3: Ciel Gris | K3: Canicule | L3: Vol / Vent Violent | M3: Pouvoir Lunaire | N3: Dracochoc | O3: Berceuse | P3: Requiem | Q3: =COUNTA(K3:P3)
A4: Frère Boule | B4: Groupe 1 - Famille Raccourci | C4: 5 | D4: 3 | E4: Charmina | H4: Combat-Psy | I4: Force Pure | K4: Pied Voltige | L4: Psykoud'Boule | M4: Poing Glace | N4: Poing Éclair | O4: Gonflette | P4: Soin | Q4: =COUNTA(K4:P4)
A5: Frère Boule | B5: Groupe 1 - Famille Raccourci | C5: 5 | D5: 4 | E5: Hexadron | H5: Combat | I5: Acharné | K5: Ultime Bastion | L5: Mégacorne | M5: Close Combat | N5: Tête de Fer | O5: Contre | P5: Ténacité | Q5: =COUNTA(K5:P5)
A6: Frère Boule | B6: Groupe 1 - Famille Raccourci | C6: 5 | D6: 5 | E6: Qulbutoké | H6: Psy | I6: Marque Ombre | K6: Encore | L6: Charme | M6: Prélèvement Destin | N6: Riposte | O6: Voile Miroir | P6: Rune Protect | Q6: =COUNTA(K6:P6)
A7: Frère Boule | B7: Groupe 1 - Famille Raccourci | C7: 5 | D7: 6 | E7: Angoliath × Baggaïd (fusion) | H7: Ténèbres-Combat | I7: Farceur + Intimidation | K7: Coup Bas | L7: Gonflette | M7: Choc Émotionnel | N7: Vampipoing | O7: Mur Lumière | P7: Éboulement | Q7: =COUNTA(K7:P7)
A8: Frère Jack | B8: Sans groupe (restants) | C8: 5 | D8: 1 | E8: Drattak × Téraclope (fusion) | H8: Vol-Dragon-Spectre | I8: Impudence + Fouille | K8: Colère | L8: Déflagration | M8: Ball'Ombre | N8: Vampirisme | O8: Séisme | P8: Danse Draco | Q8: =COUNTA(K8:P8)
A9: Frère Jack | B9: Sans groupe (restants) | C9: 5 | D9: 2 | E9: Unjoy | H9: Spectre | I9: Analyste | K9: Vœu | L9: Feu Follet | M9: Châtiment | N9: Abri | O9: Malédiction | P9: Plénitude | Q9: =COUNTA(K9:P9)
A10: Frère Jack | B10: Sans groupe (restants) | C10: 5 | D10: 3 | E10: Neitram | H10: Psy | I10: Analyste | K10: Prescience | L10: Soin | M10: Force Cosmique | N10: Machination | O10: Force Ajoutée | P10: Tonnerre | Q10: =COUNTA(K10:P10)
A11: Frère Jack | B11: Sans groupe (restants) | C11: 5 | D11: 4 | E11: Ossatueur d'Alola | H11: Spectre-Feu | I11: Paratonnerre | K11: Os Ombre | L11: Boutefeu | M11: Danse Lames | N11: Osmerang | O11: Casse-Brique | P11: Requiem | Q11: =COUNTA(K11:P11)
A12: Frère Jack | B12: Sans groupe (restants) | C12: 5 | D12: 5 | E12: Tutétékri | H12: Spectre-Sol | I12: Âme Vagabonde | K12: Prélèvement Destin | L12: Abri | M12: Regard Noir | N12: Ball'Ombre | O12: Telluriforce | P12: Feu Follet | Q12: =COUNTA(K12:P12)
A13: Frère Jack | B13: Sans groupe (restants) | C13: 5 | D13: 6 | E13: Sharpédo | H13: Ténèbres-Eau | I13: Turbo | K13: Mâchouille | L13: Aqua-Brèche | M13: Ténacité | N13: Eau Revoir | O13: Psycho-Croc | P13: Close Combat | Q13: =COUNTA(K13:P13)
... A19: Frère Pierrot | B19: Sans groupe (restants) | C19: 5 | D19: 6 | E19: Empiflor | H19: Plante-Poison | I19: Chlorophylle | K19: Lame Feuille | L19: Mégafouet | M19: Poudre Dodo | N19: Suc Digestif | O19: Bombe Beurk | P19: Danse Lames | Q19: =COUNTA(K19:P19)
A20: Frère Rapace | B20: Groupe 3 | C20: 5 | D20: 1 | E20: Ténéfix | H20: Ténèbres-Spectre | I20: Farceur | K20: Larcin | L20: Bluff | M20: Hantise | N20: Dernier Mot | O20: Feu Follet | Q20: =COUNTA(K20:P20)
A21: Frère Rapace | B21: Groupe 3 | C21: 5 | D21: 2 | E21: Rapasdepic × Spiritomb (fusion) | H21: Vol-Ténèbres | I21: Sniper | K21: Puissance | L21: Aéropique | M21: Ailes d'Acier | N21: Représailles | O21: Tricherie | P21: Cent Rancunes | Q21: =COUNTA(K21:P21)
A22: Frère Rapace | B22: Groupe 3 | C22: 5 | D22: 3 | E22: Grodrive | H22: Spectre-Vol | I22: Boom Final | K22: Ball'Ombre | L22: Feu Ensorcelé | M22: Stockage | N22: Relâche | O22: Tonnerre | Q22: =COUNTA(K22:P22)
A23: Frère Rapace | B23: Groupe 3 | C23: 5 | D23: 4 | E23: Ymphect | H23: Roche-Sol | I23: Mue | K23: Tempête de Sable | L23: Séisme | M23: Lame de Roc | N23: Grincement | O23: Pouvoir Antique | Q23: =COUNTA(K23:P23)
A24: Frère Rapace | B24: Groupe 3 | C24: 5 | D24: 5 | E24: Crustabri | H24: Eau-Glace | I24: Multi-Coups | K24: Chute Glace | L24: Coqui-Lame | M24: Stalactite | N24: Boule-Roc | O24: Saumure | Q24: =COUNTA(K24:P24)
A25: Frère Rapace | B25: Groupe 3 | C25: 5 | D25: 6 | E25: Mackogneur | H25: Combat | I25: Annule Garde | K25: Escalade | L25: Dynamopoing | M25: Gonflette | N25: Éclate-Roc | O25: Vampi-Poing | P25: Ultimawashi | Q25: =COUNTA(K25:P25)
A26: Frère Dictateur | B26: Groupe 4 | C26: 4 | D26: 1 | E26: Dimoret | H26: Ténèbres-Glace | I26: Pickpocket | K26: Éclats Glace | L26: Tranche-Nuit | M26: Chute Glace | N26: Danse Lames | O26: Poing Glace | P26: Casse-Brique | Q26: =COUNTA(K26:P26)
A27: Frère Dictateur | B27: Groupe 4 | C27: 4 | D27: 2 | E27: Zoroark | H27: Ténèbres | I27: Illusion | K27: Explonuit | L27: Tricherie | M27: Machination | N27: Lance-Flammes | O27: Exploforce | P27: Demi-Tour | Q27: =COUNTA(K27:P27)
A28: Frère Dictateur | B28: Groupe 4 | C28: 4 | D28: 3 | E28: Cizayox | H28: Insecte-Acier | I28: Technicien | K28: Pisto-Poing | L28: Plaie Croix | M28: Tête de Fer | N28: Danse Lames | O28: Demi-Tour | P28: Casse-Brique | Q28: =COUNTA(K28:P28)
A29: Frère Dictateur | B29: Groupe 4 | C29: 4 | D29: 4 | E29: Étouraptor | H29: Normal-Vol | I29: Intimidation | K29: Rapace | L29: Close Combat | M29: Vive-Attaque | N29: Demi-Tour | O29: Vol | P29: Atterrissage | Q29: =COUNTA(K29:P29)
A30: Frère Dictateur | B30: Groupe 4 | C30: 4 | D30: 5 | E30: Persian d'Alola | H30: Ténèbres | I30: Toison Épaisse | K30: Vibrobscur | L30: Rayon Gemme | M30: Bluff | N30: Machination | O30: Tricherie | P30: Dernier Mot | Q30: =COUNTA(K30:P30)
A31: Frère Dictateur | B31: Groupe 4 | C31: 4 | D31: 6 | E31: Flambusard | H31: Feu-Vol | I31: Ailes Bourrasque | K31: Rapace | L31: Boutefeu | M31: Vive-Attaque | N31: Nitrocharge | O31: Danse Lames | P31: Atterrissage | Q31: =COUNTA(K31:P31)
A32: Frère Fouras | B32: Groupe 1 - Famille Raccourci | C32: 4 | D32: 1 | E32: Trépassable | H32: Sol-Spectre | I32: Sable Humide | K32: Amass'Sable | L32: Giga-Sangsue | M32: Ball'Ombre | N32: Telluriforce | O32: Mur de Fer | P32: Hypnose | Q32: =COUNTA(K32:P32)
A33: Frère Fouras | B33: Groupe 1 - Famille Raccourci | C33: 4 | D33: 2 | E33: Dolman | H33: Roche | I33: Cercle d'Énergie | K33: Big Splash | L33: Tacle Lourd | M33: Garde Large | N33: Lame de Roc | O33: Cavalerie Lourde | P33: Poliroche | Q33: =COUNTA(K33:P33)
A34: Frère Fouras | B34: Groupe 1 - Famille Raccourci | C34: 4 | D34: 3 | E34: Apireine | H34: Vol-Insecte | I34: Pression | K34: Appel Attak | L34: Appel Défense | M34: Appel Soins | N34: Lame d'Air | O34: Aromathérapie | P34: Prélèvement du Destin | Q34: =COUNTA(K34:P34)
A35: Frère Fouras | B35: Groupe 1 - Famille Raccourci | C35: 4 | D35: 4 | E35: Maraiste | H35: Eau-Sol | I35: Inconscient | K35: Soin | L35: Hydro-Queue | M35: Séisme | N35: Bâillement | O35: Avalanche | P35: Picots | Q35: =COUNTA(K35:P35)
A36: Frère Fouras | B36: Groupe 1 - Famille Raccourci | C36: 4 | D36: 5 | E36: Braisillon | H36: Feu-Vol | I36: Ailes Bourrasque | K36: Acrobatie | L36: Demi-Tour | M36: Vol | N36: Vent Arrière | O36: Nitrocharge | P36: Feu Follet | Q36: =COUNTA(K36:P36)
... A49: Sœur Vouivre | B49: Groupe 4 | C49: 4 | D49: 6 | E49: Séviper | H49: Poison | I49: Mue | K49: Crochet Venin | L49: Tranche-Nuit | M49: Regard Médusant | N49: Danse Lames | O49: Séisme | P49: Queue de Fer | Q49: =COUNTA(K49:P49)
A50: Frère Menu | B50: Groupe 2 | C50: 3 | D50: 1 | E50: Cupcanaille | H50: Fée | I50: Délestage | J50: Baie Sitrus | K50: Croco-Larme | L50: Coto-Garde | M50: Toile Gluante | N50: Mur Lumière | O50: Vampibaiser | Q50: =COUNTA(K50:P50)
A51: Frère Menu | B51: Groupe 2 | C51: 3 | D51: 2 | E51: Sorbouboul | H51: Glace | I51: Alerte Neige | K51: Blizzard | L51: Voile Aurore | M51: Lyophilisation | N51: Chute Glace | O51: Explosion | Q51: =COUNTA(K51:P51)
A52: Frère Menu | B52: Groupe 2 | C52: 3 | D52: 3 | E52: Charmilly | H52: Fée | I52: Aroma-Voile | K52: Doux Baiser | L52: Nappage | M52: Éclat Magique | N52: Psyko | O52: Attraction | Q52: =COUNTA(K52:P52)
A53: Frère Menu | B53: Groupe 2 | C53: 3 | D53: 4 | E53: Dratatin | H53: Plante-Dragon | I53: Isograisse | K53: Dracochoc | L53: Acide Malique | M53: Éco-Sphère | N53: Giga-Sangsue | O53: Gyroballe | Q53: =COUNTA(K53:P53)
A54: Frère Menu | B54: Groupe 2 | C54: 3 | D54: 5 | E54: Arboliva | H54: Plante-Normal | I54: Récolte | J54: Baie Sitrus | K54: Tempête Verte | L54: Boule Pollen | M54: Vampigraine | N54: Éco-Sphère | Q54: =COUNTA(K54:P54)
A55: Sœur Dame Blanche | B55: Groupe 1 - Famille Raccourci | C55: 3 | D55: 1 | E55: Dedenne | H55: Électrik-Fée | I55: Bajoues | J55: Baie Sitrus | K55: Frotte-Frimousse | L55: Coup d'Jus | M55: Câlinerie | N55: Charme | O55: Attraction | P55: Ten-Danse | Q55: =COUNTA(K55:P55)
A56: Sœur Dame Blanche | B56: Groupe 1 - Famille Raccourci | C56: 3 | D56: 2 | E56: Wimessir (femelle) | H56: Normal-Psy | I56: Créa-Psy | K56: Plénitude | L56: Feuille Magik | M56: Feu Ensorcelé | N56: Vampibaiser | O56: Rafale Psy | P56: Force Ajoutée | Q56: =COUNTA(K56:P56)
A57: Sœur Dame Blanche | B57: Groupe 1 - Famille Raccourci | C57: 3 | D57: 3 | E57: Terracool | H57: Sol-Plante | I57: Force Fongique | K57: Méga-Sangsue | L57: Spore | M57: Châtiment | N57: Tir de Boue | O57: Tricherie | P57: Picots | Q57: =COUNTA(K57:P57)
...

Sheet Lisez-moi
A1: Mode d'emploi
A3: Source | B3: Tout vient uniquement de ce qui a été posté dans la conversation. Rien n'a été inventé ni complété de mémoire : une case vide est une donnée jamais donnée.
A4: Où saisir | B4: On ne saisit que dans « Compétences » et « Équipes Pokémon » : une ligne par compétence, une ligne par Pokémon. Les onglets « Récap troufions » et « Compétences officielles » se mettent à jour tout seuls.
A5: Compétence officielle | B5: Colonne E de l'onglet Compétences : liste déroulante limitée aux 18 compétences officielles. C'est elle que lisent les totaux — la colonne D ne garde que le libellé tel qu'il avait été posté, pour retrouver la source.
A6: Colonnes calculées | B6: Récap H, I, K, L, N et Équipes Q sont des formules. Ne pas y écrire à la main : recopier la formule de la ligne du dessus pour un nouveau personnage.
A7: Budget attendu | B7: Récap colonne J = 2 + 2 × badges, vérifié sur les 20 troufions sans exception. Affiche « n/a » pour les Évêques Sombres, qui suivent une grille de rang.
A8: Nb attendu (Pokémon) | B8: Récap colonne M = badges + 2, plafonné à 6. Même portée : troufions seulement.
A9: Écart | B9: Zéro = conforme au barème. Une valeur négative = il manque des points ou un Pokémon. « n/c » = donnée pas encore postée, donc rien à comparer.
A10: Code couleur | B10: Jaune = donnée jamais communiquée, à récupérer. Rouge dans les colonnes « Écart » = personnage en dessous du barème. Rouge dans la colonne « Valeur » de l'onglet Compétences = malus volontaire (seul cas : Athlétisme −2 de Frère Menu). Bleu clair = libellé de compétence corrigé vers son nom officiel. Mauve = compétence cachée ou réservée aux PNJ.
A11: Exemple de saisie | B11: Onglet Compétences : « Frère Untel | Groupe 2 | 2 | Stratège | Stratégie | 2 » — colonne 4 le libellé posté, colonne 5 le libellé normalisé. Onglet Équipes : « Frère Untel | Groupe 2 | 2 | 1 | Rattata | | Normal | Agitation | | Vive-Attaque | Morsure | ... ».
A12: Filtres | B12: Les trois onglets de données ont un filtre automatique : on peut isoler un groupe, un palier de badges, ou toutes les équipes contenant un type donné.
A13: Compétences officielles | B13: L'onglet a été supprimé. La liste déroulante de la colonne E de « Compétences » contient désormais les 18 libellés en dur : Stratège, Coach, Observateur, Social, Psychologue, Chuchoteur, Naturalisme, Secourisme, Survivaliste, Athlétisme, Infiltrateur, Cuisine, Technicien, Marchand, Baston, Ésotérisme, Théologie, Construction.
A14: Colonnes Portrait | B14: Deux portraits par personnage : « cultiste » (tenue et rôle au sein de l'Ordre) et « civil » (identité de couverture). Cas particulier de Modulo, personnage à deux voix : la colonne cultiste porte Ren (persona masculine, combat, voix de la secte) et la colonne civile porte Run (persona féminine, scène et idol). Cellule vide et colorée = portrait pas encore fourni.

Sheet Groupes
A1: Répartition en groupes (telle que postée)
A3: Groupe 1 - Famille Raccourci | B3: Frère Boule | C3: 5 | D3: Oui | E3: Troufion
A4: Groupe 1 - Famille Raccourci | B4: Frère Fouras | C4: 4 | D4: Oui | E4: Troufion
A5: Groupe 1 - Famille Raccourci | B5: Sœur Dame Blanche | C5: 3 | D5: Oui | E5: Troufion
A6: Groupe 1 - Famille Raccourci | B6: Frère Tigre | C6: 2 | D6: Oui | E6: Troufion
A7: Groupe 1 - Famille Raccourci | B7: Frère Passe | C7: 1 | D7: Oui | E7: Troufion
A8: Groupe 2 | B8: Frère Jack | C8: 5 | D8: Oui | E8: Troufion
A9: Groupe 2 | B9: Sœur Vouivre | C9: 4 | D9: Oui | E9: Troufion
A10: Groupe 2 | B10: Frère Menu | C10: 3 | D10: Oui | E10: Troufion
A11: Groupe 2 | B11: Sœur Gardienne | C11: 3 | D11: Oui | E11: Troufion
A12: Groupe 2 | B12: Frère Bihainebi (Denis) | C12: 2 | D12: Oui | E12: Troufion
A13: Groupe 2 | B13: Frère Pump | C13: 2 | D13: Oui | E13: Troufion
A14: Groupe 2 | B14: Frère Dump | C14: 2 | D14: Oui | E14: Troufion
... A18: Groupe 3 | B18: Sœur Ours | C18: 1 | D18: Oui | E18: Troufion
A19: Groupe 3 | B19: Frère Dark | C19: — | D19: Oui | E19: PJ — Évêque Sombre
A20: Groupe 3 | B20: Sœur Automne | C20: — | D20: Oui | E20: PJ — Évêque Sombre
A21: Groupe 4 | B21: Frère Pierrot | C21: 5 | D21: Oui | E21: Troufion
A22: Groupe 4 | B22: Frère Dictateur | C22: 4 | D22: Oui | E22: Troufion
A23: Groupe 4 | B23: Sœur Pie | C23: 3 | D23: Oui | E23: Troufion
A24: Groupe 4 | B24: Modulo | C24: — | D24: Oui | E24: PJ — Évêque Sombre
A25: Sans groupe (restants) | B25: Frère Nasse | C25: 1 | D25: Oui | E25: Troufion
A26: Logistique | B26: Bardella | C26: — | D26: Non | E26: —
A28: Composition du Groupe 2 (« groupe du ballon ») — 8 membres :
A29: 2 techniciens (Pump, Dump) · 3 boomers (Bihainebi, Menu, Gardienne) · 1 jeunot en soutien (Junior) · 1 chef 5 badges affinité soin + ésotérisme (Jack) · 1 seconde 4 badges (Vouivre).
A30: Frère Jack arrive en renfort directement sur les lieux (soigneur, ésotérisme : détection de présences et générateur sombre).
A31: Frère Junior surveille les arrières et prépare le repli.
A32: Famille Raccourci — note de groupe :
A33: Famille souffrant de verticalité contrariée qui a décidé de rejoindre les ADT. Elle a demandé au Pape Sombre à obtenir la possession du fort Rochefort-Canot lorsque les ADT auront pris le contrôle de la région. Nul ne sait quels rituels ils souhaitent mener en ces lieux.
A34: Conducteur du Grogrodrive : Bardella.
A35: Cité sans fiche ni palier : Bardella

Sheet À vérifier
A1: Points ouverts — mis à jour, les lignes réglées ont été retirées
A3: N° | B3: Sujet | C3: Constat | D3: Ce qu'il faudrait confirmer | E3: Statut
A4: 1 | B4: Atouts croisés à définir | C4: Cinq personnages n'ont pas d'atout croisé : Frère Menu, Frère Rapace, Sœur Automne, Modulo et Frère Jack. Colonne « Atouts croisés » ajoutée en fin de l'onglet Récap, cellules marquées À DÉFINIR. | D4: Définir les cinq atouts croisés — utiles aussi au niveau des groupes. | E4: Ouvert
A5: 2 | B5: Équipe de Sœur Automne — builds hors-standard | C5: Les 6 builds sont reçus et saisis. Points à faire valider par le MJ : (1) Big Splash sur Brutapode — capacité réelle (= Body Press) mais Brutapode n'est pas dans la liste des apprentis ; (2) méga-gemme « Kravarekite » — Kravarech n'a pas de méga-évolution officielle ; (3) Croc Fatal et Piège de Venin sur Nidoran ♀ — non trouvées dans les données consultées (BDSP), peuvent exister dans une autre génération, à confirmer. | D5: Faire valider les 3 points hors-standard par le MJ. | E5: Partiel
A6: 3 | B6: Talents de l'équipe de Dark | C6: Quatre talents connus : Malvalame Torche/Armurouillée, Lucario Cœur Noble, Tyranocif Sable Volant, Ectoplasma Lévitation (tranché par le MJ). Restent Delta Mucuscule et Flambusard. | D6: Les deux derniers talents de l'équipe de Dark. | E6: Partiel
A7: 4 | B7: Demandes de Modulo en attente | C7: Deux remplacements d'attaque sont demandés et pas encore validés : Psybeam → Psyko sur Moka, Aurora Beam → Laser Glace sur Ondine. | D7: Accord ou refus du MJ. | E7: Ouvert
A8: 5 | B8: Talent « Sniper Puissance » | C8: Chez Sœur Gardienne (Hypocéan) et Frère Rapace (Rapasdepic/Spiritomb), on lit « Talent Sniper Puissance … ». « Puissance » a été compté comme une attaque : c'est le seul découpage qui donne le bon nombre d'attaques dans les deux cas. | D8: Confirmer que Puissance est bien une attaque et non la seconde moitié du talent. | E8: Ouvert
A9: 6 | B9: Fusions | C9: Quatre entrées sont des fusions ou des doubles : Angoliath × Baggaïd (Frère Boule), Mimidrive (Frère Pierrot), Rapasdepic/Spiritomb (Frère Rapace), Drattak × Téraclope (Frère Jack). | D9: La fusion compte-t-elle pour un ou deux emplacements d'équipe ? | E9: Ouvert
A10: 7 | B10: « Stickers » | C10: Rien dans ce qui a été posté ne porte ce nom : le tableur couvre les compétences, les badges et les équipes. | D10: Ce que « stickers » désigne exactement — j'ajoute la colonne dès que c'est clair. | E10: Ouvert
